Workbook

Sheet JAN
A1: POSISI STOCK TML JANUARI 2026 ( KG )
A3: STOCK | C3: 2 | D3: 3 | E3: 5 | F3: 6 | G3: 7 | H3: 8 | I3: 9 | J3: 10 | K3: 12 | L3: 13 | M3: 14 | N3: 15 | O3: 17 | P3: 19 | Q3: 20 | R3: 21 | S3: 22 | T3: 23 | U3: 24 | V3: 26 | W3: 27 | X3: 28 | Y3: 29 | Z3: 30 | AA3: 31 | AB3: AVERAGE
A5: BAHAN BAKU | B5: CRC | C5: 7401503 | D5: 7114343 | E5: 7500053 | F5: 7732833 | G5: 8652623 | H5: 9041233 | I5: 9751158 | J5: 10189408 | K5: 10737208 | L5: 10993738 | M5: 7866943 | N5: 7114813 | O5: 8543693 | P5: 8771248 | Q5: 8667538 | R5: 8770608 | S5: 8735048 | T5: 5883423 | U5: 6162303 | V5: 6117743 | W5: 6164718 | X5: 5844008 | Y5: 5077378 | Z5: 4932178 | AA5: 5059648 | AB5: =AVERAGE(C5:AA5) -> 7713015.6
B6: ALLUMUNIUM | C6: 337819 | D6: 330793 | E6: 330793 | F6: 330793 | G6: 330793 | H6: 330793 | I6: 330793 | J6: 330793 | K6: 305487 | L6: 302673 | M6: 285819 | N6: 280191 | O6: 260493 | P6: 243605 | Q6: 237989 | R6: 235181 | S6: 231015 | T6: 151043 | U6: 140302 | V6: 114375 | W6: 101034 | X6: 90125 | Y6: 82086 | Z6: 51282 | AA6: 41918 | AB6: =AVERAGE(C6:AA6) -> 232319.52
B7: ZINC | C7: 518311 | D7: 518311 | E7: 518311 | F7: 518311 | G7: 518311 | H7: 518311 | I7: 518311 | J7: 518311 | K7: 503921 | L7: 493987 | M7: 479653 | N7: 479653 | O7: 468615 | P7: 449879 | Q7: 447682 | R7: 442183 | S7: 514125 | T7: 507504 | U7: 650824 | V7: 626555 | W7: 626555 | X7: 621033 | Y7: 612219 | Z7: 592357 | AA7: 587945 | AB7: =AVERAGE(C7:AA7) -> 530047.12
B8: ALKALI | C8: 6000 | D8: 3600 | E8: 3600 | F8: 3600 | G8: 3600 | H8: 3600 | I8: 3600 | J8: 3600 | K8: 3600 | L8: 3600 | M8: 6000 | N8: 6000 | O8: 6000 | P8: 3600 | Q8: 3600 | R8: 3600 | S8: 7200 | T8: 7200 | U8: 7200 | V8: 4800 | W8: 4800 | X8: 4800 | Y8: 4800 | Z8: 8400 | AA8: 6000 | AB8: =AVERAGE(C8:AA8) -> 4896
B9: RESIN | C9: 38620 | D9: 38620 | E9: 37620 | F9: 37620 | G9: 37620 | H9: 37620 | I9: 37620 | J9: 37620 | K9: 36340 | L9: 35340 | M9: 35340 | N9: 34340 | O9: 38260 | P9: 35260 | Q9: 33260 | R9: 31260 | S9: 37260 | T9: 36260 | U9: 34980 | V9: 31980 | W9: 29980 | X9: 34980 | Y9: 32980 | Z9: 37980 | AA9: 35980 | AB9: =AVERAGE(C9:AA9) -> 35789.6
B10: PRD | C10: 413487 | D10: 414492 | E10: 324498 | F10: 149876 | G10: 96988 | H10: 96988 | I10: 96988 | J10: 96988 | K10: 603736 | L10: 671768 | M10: 584915 | N10: 678736 | O10: 539478 | P10: 539478 | Q10: 539478 | R10: 688545 | S10: 729570 | T10: 815662 | U10: 975277 | V10: 648500 | W10: 763218 | X10: 845430 | Y10: 628638 | Z10: 420528 | AA10: 321606 | AB10: =AVERAGE(C10:AA10) -> 507394.72
B11: QA | C11: 117134 | D11: 117134 | E11: 185644 | F11: 185934 | G11: 185934 | H11: 185934 | I11: 185934 | J11: 185934 | K11: 185934 | L11: 185934 | M11: 185934 | N11: 81944 | O11: 85037 | P11: 85037 | Q11: 85037 | R11: 103622 | S11: 103622 | T11: 103622 | U11: 103622 | V11: 103622 | W11: 103622 | X11: 121802 | Y11: 121802 | Z11: 121252 | AA11: 107053 | AB11: =AVERAGE(C11:AA11) -> 133523.2
A12: BARANG JADI | B12: NEXALUME PRIME | C12: 2294133 | D12: 2194970 | E12: 2547359 | F12: 2476600 | G12: 2172979 | H12: 1688357 | I12: 1036280 | J12: 797647 | K12: 975011 | L12: 1420179 | M12: 1406210 | N12: 1394081 | O12: 1338796 | P12: 1610146 | Q12: 1628492 | R12: 1813513 | S12: 1900631 | T12: 2159425 | U12: 2036437 | V12: 2944514 | W12: 2753372 | X12: 2955106 | Y12: 3108310 | Z12: 3310591 | AA12: 3116002 | AB12: =AVERAGE(C12:AA12) -> 2043165.6
B13: TATALUME PRIME | C13: 209955 | D13: 219298 | E13: 222975 | F13: 260277 | G13: 214683 | H13: 179000 | I13: 180433 | J13: 118925 | K13: 118925 | L13: 205150 | M13: 198063 | N13: 197785 | O13: 204277 | P13: 215392 | Q13: 199779 | R13: 162886 | S13: 135921 | T13: 154487 | U13: 364700 | V13: 364700 | W13: 392314 | X13: 386906 | Y13: 332148 | Z13: 357421 | AA13: 383531 | AB13: =AVERAGE(C13:AA13) -> 239197.24
B14: NEXCOLOR PRIME | C14: 9297 | D14: 10957 | E14: 10957 | F14: 25956 | G14: 25956 | H14: 9297 | I14: 9297 | J14: 9297 | K14: 9297 | L14: 9297 | M14: 9297 | N14: 9796 | O14: 9796 | P14: 9796 | Q14: 9796 | R14: 9796 | S14: 9796 | T14: 9796 | U14: 9796 | V14: 18500 | W14: 16135 | X14: 16135 | Y14: 16135 | Z14: 16135 | AA14: 16135 | AB14: =AVERAGE(C14:AA14) -> 12657.92
B15: NEXIUM PRIME | C15: 573687 | D15: 573687 | E15: 573687 | F15: 573687 | G15: 573616 | H15: 573616 | I15: 565863 | J15: 565863 | K15: 519199 | L15: 519199 | M15: 519040 | N15: 442310 | O15: 441449 | P15: 439250 | Q15: 439250 | R15: 439250 | S15: 402430 | T15: 402430 | U15: 390199 | V15: 390199 | W15: 390199 | X15: 390199 | Y15: 390199 | Z15: 390199 | AA15: 390190 | AB15: =AVERAGE(C15:AA15) -> 474755.88
B16: COIL TATA SENTOSA | C16: 1120912.5 | D16: 1120912.5 | E16: 1120912.5 | F16: 1088523.5 | G16: 1088523.5 | H16: 1088523.5 | I16: 1038847.5 | J16: 1038847.5 | K16: 973289 | L16: 973289 | M16: 953141 | N16: 909364 | O16: 909364 | P16: 909364 | Q16: 935511 | R16: 935511 | S16: 922568 | T16: 922568 | U16: 922568 | V16: 889890 | W16: 889890 | X16: 889890 | Y16: 889890 | Z16: 889890 | AA16: 889890 | AB16: =AVERAGE(C16:AA16) -> 972475.2
B17: COIL TATALOGAM | C17: 2810670 | D17: 2810670 | E17: 3868380 | F17: 3594244 | G17: 3170143 | H17: 3170143 | I17: 2919684 | J17: 2589073.5 | K17: 2330116.5 | L17: 2060381.5 | M17: 2060381.5 | N17: 2060381.5 | O17: 1445506.5 | P17: 1445506.5 | Q17: 1407853.5 | R17: 1407853.5 | S17: 1334516.5 | T17: 1333721.5 | U17: 1310176.5 | V17: 1240905.5 | W17: 1220426.5 | X17: 1184106.5 | Y17: 1007087.5 | Z17: 1354329.5 | AA17: 1354329.5 | AB17: =AVERAGE(C17:AA17) -> 2019623.5
B18: NEXALUME MEDIUM | C18: 1145357 | D18: 1147833 | E18: 1147833 | F18: 1147833 | G18: 1162965 | H18: 1162965 | I18: 1162965 | J18: 1162965 | K18: 1164961 | L18: 1165896 | M18: 1165896 | N18: 1168995 | O18: 1174862 | P18: 1174862 | Q18: 1174862 | R18: 721057 | S18: 721057 | T18: 721057 | U18: 695531 | V18: 695531 | W18: 694359 | X18: 694359 | Y18: 694359 | Z18: 694359 | AA18: 694359 | AB18: =AVERAGE(C18:AA18) -> 978283.12
B19: NEXALUME SECOND | C19: 129396 | D19: 137615 | E19: 137615 | F19: 137615 | G19: 141204 | H19: 141204 | I19: 141204 | J19: 141204 | K19: 154188 | L19: 154188 | M19: 154188 | N19: 153522 | O19: 148091 | P19: 148091 | Q19: 148091 | R19: 68259 | S19: 68259 | T19: 68259 | U19: 49747 | V19: 51810 | W19: 51810 | X19: 51810 | Y19: 51810 | Z19: 51810 | AA19: 51810 | AB19: =AVERAGE(C19:AA19) -> 109312
B20: COIL SLITTING | C20: 299361 | D20: 321317 | E20: 361850 | F20: 405352 | G20: 398011 | H20: 503801 | I20: 569518 | J20: 481810 | K20: 592670 | L20: 638390 | M20: 790873 | N20: 810719 | O20: 725042 | P20: 725042 | Q20: 725042 | R20: 908792 | S20: 1151697 | T20: 1205009 | U20: 1152846 | V20: 945300 | W20: 878799 | X20: 653394 | Y20: 548558 | Z20: 614753 | AA20: 586643 | AB20: =AVERAGE(C20:AA20) -> 679783.56
B21: PRD | C21: 739922 | D21: 894664 | E21: 763418 | F21: 719873 | G21: 564298 | H21: 244112 | I21: 405960 | J21: 263701 | K21: 426845 | L21: 407772 | M21: 568514 | N21: 335381 | O21: 306842 | P21: 306842 | Q21: 306842 | R21: 551884 | S21: 518893 | T21: 366099 | U21: 273339 | V21: 822590 | W21: 633969 | X21: 660048 | Y21: 707754 | Z21: 247365 | AA21: 139994 | AB21: =AVERAGE(C21:AA21) -> 487076.84
B22: QA | C22: 61824 | D22: 60525 | E22: 74206 | F22: 80360 | G22: 41561 | H22: 56835 | I22: 56835 | J22: 25635 | K22: 71929 | L22: 83905 | M22: 84031 | N22: 72055 | O22: 107071 | P22: 107071 | Q22: 107071 | R22: 104521 | S22: 114795 | T22: 155419 | U22: 143638 | V22: 132653 | W22: 119863 | X22: 53281 | Y22: 56941 | Z22: 55615 | AA22: 68035 | AB22: =AVERAGE(C22:AA22) -> 83827
B23: DOWNGRADE | C23: 146623 | D23: 147496 | E23: 147496 | F23: 147496 | G23: 147496 | H23: 147496 | I23: 147615 | J23: 147615 | K23: 160498 | L23: 160498 | M23: 160498 | N23: 160498 | O23: 164601 | P23: 164601 | Q23: 164601 | R23: 167209 | S23: 167209 | T23: 167268 | U23: 167268 | V23: 167268 | W23: 171792 | X23: 171792 | Y23: 171792 | Z23: 171792 | AA23: 172905 | AB23: =AVERAGE(C23:AA23) -> 160456.92
A24: LIMBAH | B24: DROSS | C24: 3805.5 | D24: 3805.5 | E24: 3805.5 | F24: 0 | G24: 0 | H24: 2733.5 | I24: 2733.5 | J24: 2733.5 | K24: 2733.5 | L24: 3283 | M24: 3283 | N24: 3878.5 | O24: 5415.5 | P24: 5415.5 | Q24: 5415.5 | R24: 5415.5 | S24: 0 | T24: 0 | U24: 702 | V24: 1317 | W24: 3954 | X24: 4632.5 | Y24: 4632.5 | Z24: 5844.5 | AA24: 5844.5 | AB24: =AVERAGE(C24:AA24) -> 3255.36
B25: PUP COIL | C25: 14627 | D25: 14627 | E25: 14627 | F25: 14627 | G25: 14627 | H25: 14627 | I25: 14627 | J25: 14627 | K25: 16275 | L25: 16275 | M25: 16275 | N25: 16275 | O25: 16275 | P25: 16275 | Q25: 16275 | R25: 16275 | S25: 16275 | T25: 16275 | U25: 16275 | V25: 16275 | W25: 16275 | X25: 16275 | Y25: 16275 | Z25: 16275 | AA25: 16275 | AB25: =AVERAGE(C25:AA25) -> 15747.64

Sheet KAPASITAS JAN
A1: CRC - JANUARI 2026
A2: TGL | B2: STOCK | D2: TOTAL STOCK | E2: KAP | F2: TREND
B3: WH | C3: PRD & QA
A4: 2 | B4: =JAN!C5/1000 -> 7401.503 | C4: =(JAN!C10+JAN!C11)/1000 -> 530.621 | D4: =B4+C4 -> 7932.124 | E4: 6760 | F4: =D4/E4 -> 1.1733911
A5: 3 | B5: =JAN!D5/1000 -> 7114.343 | C5: =(JAN!D10+JAN!D11)/1000 -> 531.626 | D5: =B5+C5 -> 7645.969 | E5: 6760 | F5: =D5/E5 -> 1.1310605
A6: 5 | B6: =JAN!E5/1000 -> 7500.053 | C6: =(JAN!E10+JAN!E11)/1000 -> 510.142 | D6: =B6+C6 -> 8010.195 | E6: 6760 | F6: =D6/E6 -> 1.1849401
A7: 6 | B7: =JAN!F5/1000 -> 7732.833 | C7: =(JAN!F10+JAN!F11)/1000 -> 335.81 | D7: =B7+C7 -> 8068.643 | E7: 6760 | F7: =D7/E7 -> 1.1935862
A8: 7 | B8: =JAN!G5/1000 -> 8652.623 | C8: =(JAN!G10+JAN!G11)/1000 -> 282.922 | D8: =B8+C8 -> 8935.545 | E8: 6760 | F8: =D8/E8 -> 1.3218262
A9: 8 | B9: =JAN!H5/1000 -> 9041.233 | C9: =(JAN!H10+JAN!H11)/1000 -> 282.922 | D9: =B9+C9 -> 9324.155 | E9: 6760 | F9: =D9/E9 -> 1.3793129
A10: 9 | B10: =JAN!I5/1000 -> 9751.158 | C10: =(JAN!I10+JAN!I11)/1000 -> 282.922 | D10: =B10+C10 -> 10034.08 | E10: 6760 | F10: =D10/E10 -> 1.4843314
A11: 10 | B11: =JAN!J5/1000 -> 10189.408 | C11: =(JAN!J10+JAN!J11)/1000 -> 282.922 | D11: =B11+C11 -> 10472.33 | E11: 6760 | F11: =D11/E11 -> 1.5491612
A12: 12 | B12: =JAN!K5/1000 -> 10737.208 | C12: =(JAN!K10+JAN!K11)/1000 -> 789.67 | D12: =B12+C12 -> 11526.878 | E12: 6760 | F12: =D12/E12 -> 1.7051595
A13: 13 | B13: =JAN!L5/1000 -> 10993.738 | C13: =(JAN!L10+JAN!L11)/1000 -> 857.702 | D13: =B13+C13 -> 11851.44 | E13: 6760 | F13: =D13/E13 -> 1.7531716
A14: 14 | B14: =JAN!M5/1000 -> 7866.943 | C14: =(JAN!M10+JAN!M11)/1000 -> 770.849 | D14: =B14+C14 -> 8637.792 | E14: 6760 | F14: =D14/E14 -> 1.2777799
A15: 15 | B15: =JAN!N5/1000 -> 7114.813 | C15: =(JAN!N10+JAN!N11)/1000 -> 760.68 | D15: =B15+C15 -> 7875.493 | E15: 6760 | F15: =D15/E15 -> 1.1650138
A16: 17 | B16: =JAN!O5/1000 -> 8543.693 | C16: =(JAN!O10+JAN!O11)/1000 -> 624.515 | D16: =B16+C16 -> 9168.208 | E16: 6760 | F16: =D16/E16 -> 1.3562438
A17: 19 | B17: =JAN!P5/1000 -> 8771.248 | C17: =(JAN!P10+JAN!P11)/1000 -> 624.515 | D17: =B17+C17 -> 9395.763 | E17: 6760 | F17: =D17/E17 -> 1.3899058
A18: 20 | B18: =JAN!Q5/1000 -> 8667.538 | C18: =(JAN!Q10+JAN!Q11)/1000 -> 624.515 | D18: =B18+C18 -> 9292.053 | E18: 6760 | F18: =D18/E18 -> 1.3745641
A19: 21 | B19: =JAN!R5/1000 -> 8770.608 | C19: =(JAN!R10+JAN!R11)/1000 -> 792.167 | D19: =B19+C19 -> 9562.775 | E19: 6760 | F19: =D19/E19 -> 1.4146117 | H19: PERHITUNGAN KAPASITAS : RATA-RATA BERAT PER COIL 20 TON
A20: 22 | B20: =JAN!S5/1000 -> 8735.048 | C20: =(JAN!S10+JAN!S11)/1000 -> 833.192 | D20: =B20+C20 -> 9568.24 | E20: 6760 | F20: =D20/E20 -> 1.4154201 | H20: Kapasitas | J20: 6760 | K20: Ton
A21: 23 | B21: =JAN!T5/1000 -> 5883.423 | C21: =(JAN!T10+JAN!T11)/1000 -> 919.284 | D21: =B21+C21 -> 6802.707 | E21: 6760 | F21: =D21/E21 -> 1.0063176 | H21: Posisi Stock 31 Jan 26 | J21: 5488 | K21: Ton
A22: 24 | B22: =JAN!U5/1000 -> 6162.303 | C22: =(JAN!U10+JAN!U11)/1000 -> 1078.899 | D22: =B22+C22 -> 7241.202 | E22: 6760 | F22: =D22/E22 -> 1.0711837 | H22: Kapasitas (%) | J22: =J21/J20 -> 0.81183432 | K22: Ton
A23: 26 | B23: =JAN!V5/1000 -> 6117.743 | C23: =(JAN!V10+JAN!V11)/1000 -> 752.122 | D23: =B23+C23 -> 6869.865 | E23: 6760 | F23: =D23/E23 -> 1.0162522 | H23: Kapasitas tersisa | J23: =100%-J22 -> 0.18816568 | K23: Ton
A24: 27 | B24: =JAN!W5/1000 -> 6164.718 | C24: =(JAN!W10+JAN!W11)/1000 -> 866.84 | D24: =B24+C24 -> 7031.558 | E24: 6760 | F24: =D24/E24 -> 1.0401713
A25: 28 | B25: =JAN!X5/1000 -> 5844.008 | C25: =(JAN!X10+JAN!X11)/1000 -> 967.232 | D25: =B25+C25 -> 6811.24 | E25: 6760 | F25: =D25/E25 -> 1.0075799
A26: 29 | B26: =JAN!Y5/1000 -> 5077.378 | C26: =(JAN!Y10+JAN!Y11)/1000 -> 750.44 | D26: =B26+C26 -> 5827.818 | E26: 6760 | F26: =D26/E26 -> 0.86210325
A27: 30 | B27: =JAN!Z5/1000 -> 4932.178 | C27: =(JAN!Z10+JAN!Z11)/1000 -> 541.78 | D27: =B27+C27 -> 5473.958 | E27: 6760 | F27: =D27/E27 -> 0.8097571
A28: 31 | B28: =JAN!AA5/1000 -> 5059.648 | C28: =(JAN!AA10+JAN!AA11)/1000 -> 428.659 | D28: =B28+C28 -> 5488.307 | E28: 6760 | F28: =D28/E28 -> 0.81187973
A29: AVERAGE | B29: =AVERAGE(B4:B28) -> 7713.0156 | C29: =AVERAGE(C4:C28) -> 640.91792 | D29: =AVERAGE(D4:D28) -> 8353.9335 | E29: =AVERAGE(E4:E28) -> 6760 | F29: =AVERAGE(F4:F28) -> 1.235789
A30: Stock tertinggi | B30: =MAX(B4:B28) -> 10993.738 | C30: =MAX(C4:C28) -> 1078.899 | D30: =MAX(D4:D28) -> 11851.44 | E30: 6760 | F30: =D30/E30 -> 1.7531716
A33: BARANG JADI JANUARI 2026
A34: TGL | B34: STOCK | D34: TOTAL STOCK | E34: KAP | F34: TREND
B35: WH | C35: PRD & QA
A36: 2 | B36: =(JAN!C12+JAN!C13+JAN!C14+JAN!C15+JAN!C16+JAN!C17+JAN!C18+JAN!C19+JAN!C20+JAN!C23)/1000 -> 8739.3915 | C36: =(JAN!C21+JAN!C22)/1000 -> 801.746 | D36: =B36+C36 -> 9541.1375 | E36: 12000 | F36: =D36/E36 -> 0.79509479
A37: 3 | B37: =(JAN!D12+JAN!D13+JAN!D14+JAN!D15+JAN!D16+JAN!D17+JAN!D18+JAN!D19+JAN!D20+JAN!D23)/1000 -> 8684.7555 | C37: =(JAN!D21+JAN!D22)/1000 -> 955.189 | D37: =B37+C37 -> 9639.9445 | E37: 12000 | F37: =D37/E37 -> 0.80332871
A38: 5 | B38: =(JAN!E12+JAN!E13+JAN!E14+JAN!E15+JAN!E16+JAN!E17+JAN!E18+JAN!E19+JAN!E20+JAN!E23)/1000 -> 10139.065 | C38: =(JAN!E21+JAN!E22)/1000 -> 837.624 | D38: =B38+C38 -> 10976.689 | E38: 12000 | F38: =D38/E38 -> 0.91472404
A39: 6 | B39: =(JAN!F12+JAN!F13+JAN!F14+JAN!F15+JAN!F16+JAN!F17+JAN!F18+JAN!F19+JAN!F20+JAN!F23)/1000 -> 9857.5835 | C39: =(JAN!F21+JAN!F22)/1000 -> 800.233 | D39: =B39+C39 -> 10657.817 | E39: 12000 | F39: =D39/E39 -> 0.88815138
A40: 7 | B40: =(JAN!G12+JAN!G13+JAN!G14+JAN!G15+JAN!G16+JAN!G17+JAN!G18+JAN!G19+JAN!G20+JAN!G23)/1000 -> 9095.5765 | C40: =(JAN!G21+JAN!G22)/1000 -> 605.859 | D40: =B40+C40 -> 9701.4355 | E40: 12000 | F40: =D40/E40 -> 0.80845296
A41: 8 | B41: =(JAN!H12+JAN!H13+JAN!H14+JAN!H15+JAN!H16+JAN!H17+JAN!H18+JAN!H19+JAN!H20+JAN!H23)/1000 -> 8664.4025 | C41: =(JAN!H21+JAN!H22)/1000 -> 300.947 | D41: =B41+C41 -> 8965.3495 | E41: 12000 | F41: =D41/E41 -> 0.74711246
A42: 9 | B42: =(JAN!I12+JAN!I13+JAN!I14+JAN!I15+JAN!I16+JAN!I17+JAN!I18+JAN!I19+JAN!I20+JAN!I23)/1000 -> 7771.7065 | C42: =(JAN!I21+JAN!I22)/1000 -> 462.795 | D42: =B42+C42 -> 8234.5015 | E42: 12000 | F42: =D42/E42 -> 0.68620846
...

Sheet FEB
A1: POSISI STOCK TML FEBRUARI 2026 ( KG )
A3: STOCK | C3: 2 | D3: 3 | E3: 4 | F3: 5 | G3: 6 | H3: 7 | I3: 9 | J3: 10 | K3: 11 | L3: 12 | M3: 13 | N3: 14 | O3: 16 | P3: 18 | Q3: 19 | R3: 20 | S3: 21 | T3: 23 | U3: 24 | V3: 25 | W3: 26 | X3: 27 | Y3: 28 | Z3: AVERAGE
A5: BAHAN BAKU | B5: CRC | C5: 3007580 | D5: 2824480 | E5: 3004315 | F5: 2473565 | G5: 2927515 | H5: 2631955 | I5: 2448115 | J5: 2240285 | K5: 2318845 | L5: 2186375 | M5: 2320715 | N5: 1452195 | O5: 2066135 | P5: 2315175 | Q5: 2620935 | R5: 2923755 | S5: 3971765 | T5: 4582915 | U5: 4243885 | V5: 4002785 | W5: 3688905 | X5: 3903965 | Y5: 2997345 | Z5: =AVERAGE(C5:Y5) -> 2919717.6
B6: ALLUMUNIUM | C6: 21811 | D6: 17793 | E6: 318378 | F6: 306327 | G6: 303642 | H6: 299599 | I6: 298253 | J6: 294224 | K6: 288792 | L6: 281754 | M6: 269064 | N6: 256980 | O6: 256980 | P6: 256980 | Q6: 243029 | R6: 243029 | S6: 243029 | T6: 243029 | U6: 233635 | V6: 232235 | W6: 214840 | X6: 189327 | Y6: 181285 | Z6: =AVERAGE(C6:Y6) -> 238870.22
B7: ZINC | C7: 531566 | D7: 524949 | E7: 499564 | F7: 499564 | G7: 499564 | H7: 495149 | I7: 492944 | J7: 492944 | K7: 490737 | L7: 484114 | M7: 480803 | N7: 469777 | O7: 469777 | P7: 469777 | Q7: 459848 | R7: 459848 | S7: 459848 | T7: 433866 | U7: 428343 | V7: 427242 | W7: 420632 | X7: 398582 | Y7: 383152 | Z7: =AVERAGE(C7:Y7) -> 468373.48
B8: ALKALI | C8: 6000 | D8: 6000 | E8: 6000 | F8: 6000 | G8: 3600 | H8: 3600 | I8: 7200 | J8: 7200 | K8: 7200 | L8: 4800 | M8: 2400 | N8: 2400 | O8: 3600 | P8: 3600 | Q8: 3600 | R8: 3600 | S8: 3600 | T8: 3600 | U8: 3600 | V8: 3600 | W8: 3600 | X8: 3600 | Y8: 3600 | Z8: =AVERAGE(C8:Y8) -> 4434.7826
B9: RESIN | C9: 33980 | D9: 33980 | E9: 32980 | F9: 39430 | G9: 39430 | H9: 38280 | I9: 43280 | J9: 43280 | K9: 43280 | L9: 40280 | M9: 40280 | N9: 39280 | O9: 46280 | P9: 46280 | Q9: 46280 | R9: 46580 | S9: 47580 | T9: 47280 | U9: 46280 | V9: 45498 | W9: 44478 | X9: 42478 | Y9: 39348 | Z9: =AVERAGE(C9:Y9) -> 42005.304
B10: PRD | C10: 704945 | D10: 459655 | E10: 312945 | F10: 379873 | G10: 428925 | H10: 432120 | I10: 195430 | J10: 413799 | K10: 306507 | L10: 406297 | M10: 486550 | N10: 348703 | O10: 229630 | P10: 229630 | Q10: 229630 | R10: 518900 | S10: 685470 | T10: 685870 | U10: 800341 | V10: 391871 | W10: 406605 | X10: 437968 | Y10: 254372 | Z10: =AVERAGE(C10:Y10) -> 423740.7
B11: QA | C11: 107053 | D11: 107053 | E11: 107053 | F11: 107053 | G11: 66293 | H11: 48153 | I11: 48153 | J11: 48153 | K11: 48153 | L11: 48153 | M11: 48153 | N11: 48153 | O11: 48153 | P11: 48153 | Q11: 48153 | R11: 48153 | S11: 48153 | T11: 48388 | U11: 48388 | V11: 48388 | W11: 48388 | X11: 48388 | Y11: 48388 | Z11: =AVERAGE(C11:Y11) -> 59246.478
A12: BARANG JADI | B12: NEXALUME PRIME | C12: 3833853 | D12: 3660457 | E12: 3678447 | F12: 3545224 | G12: 3282493 | H12: 2884429 | I12: 2498571 | J12: 1830594 | K12: 1770887 | L12: 1739295 | M12: 1739295 | N12: 2467543 | O12: 2050550 | P12: 1671718 | Q12: 1407773 | R12: 1190963 | S12: 1061343 | T12: 941696 | U12: 1668951 | V12: 2013873 | W12: 1566315 | X12: 1691654 | Y12: 1968057 | Z12: =AVERAGE(C12:Y12) -> 2181042.7
B13: TATALUME PRIME | C13: 424647 | D13: 420134 | E13: 450820 | F13: 494158 | G13: 450984 | H13: 499937 | I13: 496851 | J13: 378105 | K13: 418274 | L13: 423648 | M13: 356039 | N13: 297796 | O13: 237593 | P13: 267439 | Q13: 265174 | R13: 287280 | S13: 296281 | T13: 318313 | U13: 305685 | V13: 285205 | W13: 300781 | X13: 308409 | Y13: 244390 | Z13: =AVERAGE(C13:Y13) -> 357736.65
B14: NEXCOLOR PRIME | C14: 16033 | D14: 9712 | E14: 13017 | F14: 13148 | G14: 13148 | H14: 13148 | I14: 13148 | J14: 13148 | K14: 13148 | L14: 13148 | M14: 13148 | N14: 25349 | O14: 25353 | P14: 9228 | Q14: 9228 | R14: 9330 | S14: 9330 | T14: 9330 | U14: 9322 | V14: 9322 | W14: 9322 | X14: 11116 | Y14: 9322 | Z14: =AVERAGE(C14:Y14) -> 12586.87
B15: NEXIUM PRIME | C15: 390190 | D15: 406457 | E15: 432729 | F15: 432729 | G15: 435231 | H15: 435149 | I15: 435149 | J15: 435149 | K15: 399876 | L15: 402359 | M15: 459723 | N15: 460301 | O15: 412301 | P15: 412301 | Q15: 412301 | R15: 421156 | S15: 442437 | T15: 760573 | U15: 726326 | V15: 790597 | W15: 765444 | X15: 690006 | Y15: 573904 | Z15: =AVERAGE(C15:Y15) -> 501408.17
B16: COIL TATA SENTOSA | C16: 889890 | D16: 889890 | E16: 889890 | F16: 889890 | G16: 889890 | H16: 889890 | I16: 889890 | J16: 1178881 | K16: 1178881 | L16: 1178881 | M16: 1178881 | N16: 1178881 | O16: 811850 | P16: 1257165 | Q16: 1257165 | R16: 1257165 | S16: 1407841 | T16: 1392845 | U16: 1309992 | V16: 1121317 | W16: 1121317 | X16: 1121317 | Y16: 1121317 | Z16: =AVERAGE(C16:Y16) -> 1100127.2
B17: COIL TATALOGAM | C17: 1354329.5 | D17: 1332256.5 | E17: 1292802.5 | F17: 1292802.5 | G17: 971199.5 | H17: 971199.5 | I17: 948903.5 | J17: 948903.5 | K17: 948903.5 | L17: 948903.5 | M17: 948903.5 | N17: 948903.5 | O17: 809555.5 | P17: 809555.5 | Q17: 809555.5 | R17: 809555.5 | S17: 704242.5 | T17: 665245.5 | U17: 665245.5 | V17: 665245.5 | W17: 776098.5 | X17: 569439.5 | Y17: 569439.5 | Z17: =AVERAGE(C17:Y17) -> 902660.41
B18: NEXALUME MEDIUM | C18: 684091 | D18: 684091 | E18: 684091 | F18: 689420 | G18: 689420 | H18: 689420 | I18: 689420 | J18: 689420 | K18: 687157 | L18: 687157 | M18: 687157 | N18: 687157 | O18: 690794 | P18: 690794 | Q18: 690794 | R18: 690794 | S18: 690794 | T18: 688188 | U18: 688188 | V18: 688188 | W18: 712657 | X18: 712657 | Y18: 712657 | Z18: =AVERAGE(C18:Y18) -> 691500.26
B19: NEXALUME SECOND | C19: 56900 | D19: 56900 | E19: 56900 | F19: 56900 | G19: 56900 | H19: 56900 | I19: 56900 | J19: 56900 | K19: 65102 | L19: 65102 | M19: 65102 | N19: 65102 | O19: 67986 | P19: 67986 | Q19: 69457 | R19: 69457 | S19: 69457 | T19: 66025 | U19: 66025 | V19: 66025 | W19: 102157 | X19: 102157 | Y19: 102157 | Z19: =AVERAGE(C19:Y19) -> 68021.609
B20: COIL SLITTING | C20: 595822 | D20: 571656 | E20: 546163 | F20: 551108 | G20: 549397 | H20: 667942 | I20: 677518 | J20: 735052 | K20: 399117 | L20: 785272 | M20: 787565 | N20: 950787 | O20: 1041397 | P20: 1115050 | Q20: 1106271 | R20: 979071 | S20: 1003245 | T20: 1003245 | U20: 959522 | V20: 875861 | W20: 871040 | X20: 1073656 | Y20: 1194428 | Z20: =AVERAGE(C20:Y20) -> 827834.13
B21: PRD | C21: 139249 | D21: 225596 | E21: 494930 | F21: 558467 | G21: 432416 | H21: 573817 | I21: 850672 | J21: 728328 | K21: 550456 | L21: 695673 | M21: 544482 | N21: 462138 | O21: 353767 | P21: 239946 | Q21: 156842 | R21: 213057 | S21: 99141 | T21: 275411 | U21: 279165 | V21: 445829 | W21: 505337 | X21: 328009 | Y21: 259039 | Z21: =AVERAGE(C21:Y21) -> 409207.26
B22: QA | C22: 59819 | D22: 89668 | E22: 74624 | F22: 92223 | G22: 43586 | H22: 70221 | I22: 36625 | J22: 30196 | K22: 48834 | L22: 44728 | M22: 26854 | N22: 27928 | O22: 29754 | P22: 29754 | Q22: 54628 | R22: 28791 | S22: 24422 | T22: 234829 | U22: 94989 | V22: 85332 | W22: 88323 | X22: 83141 | Y22: 61084 | Z22: =AVERAGE(C22:Y22) -> 63493.609
B23: DOWNGRADE | C23: 172905 | D23: 172905 | E23: 172921 | F23: 172921 | G23: 172921 | H23: 172921 | I23: 172921 | J23: 172921 | K23: 175744 | L23: 175744 | M23: 175744 | N23: 175744 | O23: 175744 | P23: 175744 | Q23: 175840 | R23: 175840 | S23: 176000 | T23: 207809 | U23: 207809 | V23: 216779 | W23: 216779 | X23: 216779 | Y23: 216779 | Z23: =AVERAGE(C23:Y23) -> 184704.96
A24: LIMBAH | B24: DROSS | C24: 5844.5 | D24: 5844.5 | E24: 1325 | F24: 1325 | G24: 1325 | H24: 1325 | I24: 4192 | J24: 4192 | K24: 0 | L24: 0 | M24: 0 | N24: 632 | O24: 1186.5 | P24: 1186.5 | Q24: 1713 | R24: 1713 | S24: 1713 | T24: 3351.5 | U24: 3351.5 | V24: 3351.5 | W24: 3351.5 | X24: 3351.5 | Y24: 3958.5 | Z24: =AVERAGE(C24:Y24) -> 2357.9565
B25: PUP COIL | C25: 16275 | D25: 16275 | E25: 16275 | F25: 16275 | G25: 16275 | H25: 16275 | I25: 16275 | J25: 16275 | K25: 16275 | L25: 16275 | M25: 16275 | N25: 16275 | O25: 19627 | P25: 19627 | Q25: 19627 | R25: 19627 | S25: 19627 | T25: 19627 | U25: 19627 | V25: 19627 | W25: 19627 | X25: 19627 | Y25: 19627 | Z25: =AVERAGE(C25:Y25) -> 17878.13

Sheet KAPASITAS FEB
A1: CRC - FEBRUARI 2026
A2: TGL | B2: STOCK | D2: TOTAL STOCK | E2: KAP | F2: TREND
B3: WH | C3: PRD & QA
A4: 2 | B4: =FEB!C5/1000 -> 3007.58 | C4: =(FEB!C10+FEB!C11)/1000 -> 811.998 | D4: =B4+C4 -> 3819.578 | E4: 6760 | F4: =D4/E4 -> 0.56502633
A5: 3 | B5: =FEB!D5/1000 -> 2824.48 | C5: =(FEB!D10+FEB!D11)/1000 -> 566.708 | D5: =B5+C5 -> 3391.188 | E5: 6760 | F5: =D5/E5 -> 0.50165503
A6: 4 | B6: =FEB!E5/1000 -> 3004.315 | C6: =(FEB!E10+FEB!E11)/1000 -> 419.998 | D6: =B6+C6 -> 3424.313 | E6: 6760 | F6: =D6/E6 -> 0.50655518
A7: 5 | B7: =FEB!F5/1000 -> 2473.565 | C7: =(FEB!F10+FEB!F11)/1000 -> 486.926 | D7: =B7+C7 -> 2960.491 | E7: 6760 | F7: =D7/E7 -> 0.43794246
A8: 6 | B8: =FEB!G5/1000 -> 2927.515 | C8: =(FEB!G10+FEB!G11)/1000 -> 495.218 | D8: =B8+C8 -> 3422.733 | E8: 6760 | F8: =D8/E8 -> 0.50632145
A9: 7 | B9: =FEB!H5/1000 -> 2631.955 | C9: =(FEB!H10+FEB!H11)/1000 -> 480.273 | D9: =B9+C9 -> 3112.228 | E9: 6760 | F9: =D9/E9 -> 0.46038876
A10: 9 | B10: =FEB!I5/1000 -> 2448.115 | C10: =(FEB!I10+FEB!I11)/1000 -> 243.583 | D10: =B10+C10 -> 2691.698 | E10: 6760 | F10: =D10/E10 -> 0.39818018
A11: 10 | B11: =FEB!J5/1000 -> 2240.285 | C11: =(FEB!J10+FEB!J11)/1000 -> 461.952 | D11: =B11+C11 -> 2702.237 | E11: 6760 | F11: =D11/E11 -> 0.3997392
A12: 11 | B12: =FEB!K5/1000 -> 2318.845 | C12: =(FEB!K10+FEB!K11)/1000 -> 354.66 | D12: =B12+C12 -> 2673.505 | E12: 6760 | F12: =D12/E12 -> 0.39548891
A13: 12 | B13: =FEB!L5/1000 -> 2186.375 | C13: =(FEB!L10+FEB!L11)/1000 -> 454.45 | D13: =B13+C13 -> 2640.825 | E13: 6760 | F13: =D13/E13 -> 0.39065459
A14: 13 | B14: =FEB!M5/1000 -> 2320.715 | C14: =(FEB!M10+FEB!M11)/1000 -> 534.703 | D14: =B14+C14 -> 2855.418 | E14: 6760 | F14: =D14/E14 -> 0.42239911
A15: 14 | B15: =FEB!N5/1000 -> 1452.195 | C15: =(FEB!N10+FEB!N11)/1000 -> 396.856 | D15: =B15+C15 -> 1849.051 | E15: 6760 | F15: =D15/E15 -> 0.27352825
A16: 16 | B16: =FEB!O5/1000 -> 2066.135 | C16: =(FEB!O10+FEB!O11)/1000 -> 277.783 | D16: =B16+C16 -> 2343.918 | E16: 6760 | F16: =D16/E16 -> 0.34673343
A17: 18 | B17: =FEB!P5/1000 -> 2315.175 | C17: =(FEB!P10+FEB!P11)/1000 -> 277.783 | D17: =B17+C17 -> 2592.958 | E17: 6760 | F17: =D17/E17 -> 0.38357367
A18: 19 | B18: =FEB!Q5/1000 -> 2620.935 | C18: =(FEB!Q10+FEB!Q11)/1000 -> 277.783 | D18: =B18+C18 -> 2898.718 | E18: 6760 | F18: =D18/E18 -> 0.42880444
A19: 20 | B19: =FEB!R5/1000 -> 2923.755 | C19: =(FEB!R10+FEB!R11)/1000 -> 567.053 | D19: =B19+C19 -> 3490.808 | E19: 6760 | F19: =D19/E19 -> 0.51639172 | H19: PERHITUNGAN KAPASITAS : RATA-RATA BERAT PER COIL 20 TON
A20: 21 | B20: =FEB!S5/1000 -> 3971.765 | C20: =(FEB!S10+FEB!S11)/1000 -> 733.623 | D20: =B20+C20 -> 4705.388 | E20: 6760 | F20: =D20/E20 -> 0.69606331 | H20: Kapasitas | J20: 6760 | K20: Ton
A21: 23 | B21: =FEB!T5/1000 -> 4582.915 | C21: =(FEB!T10+FEB!T11)/1000 -> 734.258 | D21: =B21+C21 -> 5317.173 | E21: 6760 | F21: =D21/E21 -> 0.78656405 | H21: Posisi Stock 28 Feb 26 | J21: 3300 | K21: Ton
A22: 24 | B22: =FEB!U5/1000 -> 4243.885 | C22: =(FEB!U10+FEB!U11)/1000 -> 848.729 | D22: =B22+C22 -> 5092.614 | E22: 6760 | F22: =D22/E22 -> 0.75334527 | H22: Kapasitas (%) | J22: =J21/J20 -> 0.48816568 | K22: Ton
A23: 25 | B23: =FEB!V5/1000 -> 4002.785 | C23: =(FEB!V10+FEB!V11)/1000 -> 440.259 | D23: =B23+C23 -> 4443.044 | E23: 6760 | F23: =D23/E23 -> 0.65725503 | H23: Kapasitas tersisa | J23: =100%-J22 -> 0.51183432 | K23: Ton
A24: 26 | B24: =FEB!W5/1000 -> 3688.905 | C24: =(FEB!W10+FEB!W11)/1000 -> 454.993 | D24: =B24+C24 -> 4143.898 | E24: 6760 | F24: =D24/E24 -> 0.61300266
A25: 27 | B25: =FEB!X5/1000 -> 3903.965 | C25: =(FEB!X10+FEB!X11)/1000 -> 486.356 | D25: =B25+C25 -> 4390.321 | E25: 6760 | F25: =D25/E25 -> 0.64945577
A26: 28 | B26: =FEB!Y5/1000 -> 2997.345 | C26: =(FEB!Y10+FEB!Y11)/1000 -> 302.76 | D26: =B26+C26 -> 3300.105 | E26: 6760 | F26: =D26/E26 -> 0.48818121
A27: AVERAGE | B27: =AVERAGE(B4:B26) -> 2919.7176 | C27: =AVERAGE(C4:C26) -> 482.98717 | D27: =AVERAGE(D4:D26) -> 3402.7048 | E27: =AVERAGE(E4:E26) -> 6760 | F27: =AVERAGE(F4:F26) -> 0.5033587
A28: Stock tertinggi | B28: =MAX(B4:B26) -> 4582.915 | C28: =MAX(C4:C26) -> 848.729 | D28: =MAX(D4:D26) -> 5317.173 | E28: 6760 | F28: =D28/E28 -> 0.78656405
A31: BARANG JADI FEBRUARI 2026
A32: TGL | B32: STOCK | D32: TOTAL STOCK | E32: KAP | F32: TREND
B33: WH | C33: PRD & QA
A34: 2 | B34: =(FEB!C12+FEB!C13+FEB!C14+FEB!C15+FEB!C16+FEB!C17+FEB!C18+FEB!C19+FEB!C20+FEB!C23)/1000 -> 8418.6605 | C34: =(FEB!C21+FEB!C22)/1000 -> 199.068 | D34: =B34+C34 -> 8617.7285 | E34: 12000 | F34: =D34/E34 -> 0.71814404
A35: 3 | B35: =(FEB!D12+FEB!D13+FEB!D14+FEB!D15+FEB!D16+FEB!D17+FEB!D18+FEB!D19+FEB!D20+FEB!D23)/1000 -> 8204.4585 | C35: =(FEB!D21+FEB!D22)/1000 -> 315.264 | D35: =B35+C35 -> 8519.7225 | E35: 12000 | F35: =D35/E35 -> 0.70997687
A36: 4 | B36: =(FEB!E12+FEB!E13+FEB!E14+FEB!E15+FEB!E16+FEB!E17+FEB!E18+FEB!E19+FEB!E20+FEB!E23)/1000 -> 8217.7805 | C36: =(FEB!E21+FEB!E22)/1000 -> 569.554 | D36: =B36+C36 -> 8787.3345 | E36: 12000 | F36: =D36/E36 -> 0.73227788
A37: 5 | B37: =(FEB!F12+FEB!F13+FEB!F14+FEB!F15+FEB!F16+FEB!F17+FEB!F18+FEB!F19+FEB!F20+FEB!F23)/1000 -> 8138.3005 | C37: =(FEB!F21+FEB!F22)/1000 -> 650.69 | D37: =B37+C37 -> 8788.9905 | E37: 12000 | F37: =D37/E37 -> 0.73241587
A38: 6 | B38: =(FEB!G12+FEB!G13+FEB!G14+FEB!G15+FEB!G16+FEB!G17+FEB!G18+FEB!G19+FEB!G20+FEB!G23)/1000 -> 7511.5835 | C38: =(FEB!G21+FEB!G22)/1000 -> 476.002 | D38: =B38+C38 -> 7987.5855 | E38: 12000 | F38: =D38/E38 -> 0.66563213
A39: 7 | B39: =(FEB!H12+FEB!H13+FEB!H14+FEB!H15+FEB!H16+FEB!H17+FEB!H18+FEB!H19+FEB!H20+FEB!H23)/1000 -> 7280.9355 | C39: =(FEB!H21+FEB!H22)/1000 -> 644.038 | D39: =B39+C39 -> 7924.9735 | E39: 12000 | F39: =D39/E39 -> 0.66041446
A40: 9 | B40: =(FEB!I12+FEB!I13+FEB!I14+FEB!I15+FEB!I16+FEB!I17+FEB!I18+FEB!I19+FEB!I20+FEB!I23)/1000 -> 6879.2715 | C40: =(FEB!I21+FEB!I22)/1000 -> 887.297 | D40: =B40+C40 -> 7766.5685 | E40: 12000 | F40: =D40/E40 -> 0.64721404
A41: 10 | B41: =(FEB!J12+FEB!J13+FEB!J14+FEB!J15+FEB!J16+FEB!J17+FEB!J18+FEB!J19+FEB!J20+FEB!J23)/1000 -> 6439.0735 | C41: =(FEB!J21+FEB!J22)/1000 -> 758.524 | D41: =B41+C41 -> 7197.5975 | E41: 12000 | F41: =D41/E41 -> 0.59979979
A42: 11 | B42: =(FEB!K12+FEB!K13+FEB!K14+FEB!K15+FEB!K16+FEB!K17+FEB!K18+FEB!K19+FEB!K20+FEB!K23)/1000 -> 6057.0895 | C42: =(FEB!K21+FEB!K22)/1000 -> 599.29 | D42: =B42+C42 -> 6656.3795 | E42: 12000 | F42: =D42/E42 -> 0.55469829
...

Sheet MAR
A1: POSISI STOCK TML MARET 2026 ( KG )
A3: STOCK | C3: 2 | D3: 3 | E3: 4 | F3: 5 | G3: 6 | H3: 7 | I3: 9 | J3: 10 | K3: 11 | L3: 12 | M3: 13 | N3: 14 | O3: 16 | P3: 17 | Q3: 18 | R3: 28 | S3: 30 | T3: 31 | U3: AVERAGE
A5: BAHAN BAKU | B5: CRC | C5: 1994535 | D5: 2459630 | E5: 2712150 | F5: 2694980 | G5: 2093440 | H5: 1586580 | I5: 1486860 | J5: 1604790 | K5: 1680495 | L5: 2255160 | M5: 2255160 | N5: 3045020 | O5: 1765585 | P5: 1328520 | Q5: 466460 | R5: 629095 | S5: 843255 | T5: 1632645 | U5: =AVERAGE(C5:T5) -> 1807464.4
B6: ALLUMUNIUM | C6: 173248 | D6: 169219 | E6: 169219 | F6: 169219 | G6: 162491 | H6: 159796 | I6: 318792 | J6: 545634 | K6: 318792 | L6: 318792 | M6: 308944 | N6: 307538 | O6: 256656 | P6: 348262 | Q6: 348262 | R6: 348262 | S6: 348262 | T6: 344034 | U6: =AVERAGE(C6:T6) -> 284190.11
B7: ZINC | C7: 376542 | D7: 371029 | E7: 371029 | F7: 371029 | G7: 367722 | H7: 367722 | I7: 354501 | J7: 354501 | K7: 354501 | L7: 354501 | M7: 332454 | N7: 332454 | O7: 291076 | P7: 286662 | Q7: 439433 | R7: 439433 | S7: 515274 | T7: 508658 | U7: =AVERAGE(C7:T7) -> 377140.06
B8: ALKALI | C8: 3600 | D8: 3600 | E8: 7200 | F8: 7200 | G8: 4800 | H8: 4800 | I8: 4800 | J8: 4800 | K8: 4800 | L8: 4800 | M8: 4800 | N8: 4800 | O8: 2400 | P8: 6000 | Q8: 6000 | R8: 6000 | S8: 6000 | T8: 6000 | U8: =AVERAGE(C8:T8) -> 5133.3333
B9: RESIN | C9: 36348 | D9: 36348 | E9: 43348 | F9: 43348 | G9: 41228 | H9: 41228 | I9: 37228 | J9: 37108 | K9: 37108 | L9: 37108 | M9: 37108 | N9: 36748 | O9: 32358 | P9: 38238 | Q9: 38238 | R9: 38238 | S9: 38238 | T9: 37238 | U9: =AVERAGE(C9:T9) -> 38155.778
B10: PRD | C10: 592743 | D10: 597072 | E10: 284876 | F10: 395102 | G10: 461466 | H10: 588930 | I10: 56586 | J10: 43828 | K10: 43828 | L10: 43828 | M10: 43828 | N10: 392726 | O10: 347802 | P10: 182279 | Q10: 51472 | R10: 47432 | S10: 49867 | T10: 123047 | U10: =AVERAGE(C10:T10) -> 241484
B11: QA | C11: 48388 | D11: 48388 | E11: 5363 | F11: 5363 | G11: 5363 | H11: 13511 | I11: 28846 | J11: 28846 | K11: 28846 | L11: 28846 | M11: 28846 | N11: 28846 | O11: 28846 | P11: 28846 | Q11: 28846 | R11: 28846 | S11: 29248 | T11: 28846 | U11: =AVERAGE(C11:T11) -> 26273.889
A12: BARANG JADI | B12: NEXALUME PRIME | C12: 1557979 | D12: 1703321 | E12: 1519241 | F12: 1292537 | G12: 1529040 | H12: 1766937 | I12: 2281865 | J12: 2183882 | K12: 2160928 | L12: 1868539 | M12: 1838463 | N12: 1869127 | O12: 2425121 | P12: 2753725 | Q12: 3977079 | R12: 3848382 | S12: 3424269 | T12: 1962863 | U12: =AVERAGE(C12:T12) -> 2220183.2
B13: TATALUME PRIME | C13: 252272 | D13: 252272 | E13: 264403 | F13: 274068 | G13: 291644 | H13: 251124 | I13: 318961 | J13: 318961 | K13: 292696 | L13: 314028 | M13: 197263 | N13: 221417 | O13: 226749 | P13: 226749 | Q13: 226749 | R13: 275310 | S13: 247337 | T13: 264338 | U13: =AVERAGE(C13:T13) -> 262018.94
B14: NEXCOLOR PRIME | C14: 9322 | D14: 9322 | E14: 9322 | F14: 23344 | G14: 19253 | H14: 76622 | I14: 76622 | J14: 130317 | K14: 231460 | L14: 231460 | M14: 226291 | N14: 225198 | O14: 225198 | P14: 243190 | Q14: 239351 | R14: 240627 | S14: 207235 | T14: 174531 | U14: =AVERAGE(C14:T14) -> 144370.28
B15: NEXIUM PRIME | C15: 612788 | D15: 685740 | E15: 685740 | F15: 661124 | G15: 652269 | H15: 662348 | I15: 589042 | J15: 497776 | K15: 506930 | L15: 506930 | M15: 487780 | N15: 487780 | O15: 490771 | P15: 490746 | Q15: 465627 | R15: 459667 | S15: 439862 | T15: 439862 | U15: =AVERAGE(C15:T15) -> 545710.11
B16: COIL TATA SENTOSA | C16: 1121317 | D16: 1121317 | E16: 1009568 | F16: 978994 | G16: 963990 | H16: 963990 | I16: 963990 | J16: 963990 | K16: 950193 | L16: 950193 | M16: 950193 | N16: 950193 | O16: 950193 | P16: 1033037 | Q16: 1033037 | R16: 1033037 | S16: 1033037 | T16: 1155100 | U16: =AVERAGE(C16:T16) -> 1006964.9
B17: COIL TATALOGAM | C17: 880570.5 | D17: 880570.5 | E17: 585434.5 | F17: 585434.5 | G17: 444824 | H17: 444824 | I17: 444824 | J17: 444824 | K17: 328697 | L17: 328697 | M17: 328697 | N17: 328697 | O17: 296735 | P17: 296735 | Q17: 296735 | R17: 296735 | S17: 296735 | T17: 296735 | U17: =AVERAGE(C17:T17) -> 433694.67
B18: NEXALUME MEDIUM | C18: 723874 | D18: 723874 | E18: 723874 | F18: 681071 | G18: 681071 | H18: 681071 | I18: 681071 | J18: 685065 | K18: 662292 | L18: 662292 | M18: 662292 | N18: 725520 | O18: 725520 | P18: 724944 | Q18: 718188 | R18: 718188 | S18: 718188 | T18: 729785 | U18: =AVERAGE(C18:T18) -> 701565.56
B19: NEXALUME SECOND | C19: 99722 | D19: 99722 | E19: 99722 | F19: 108854 | G19: 108854 | H19: 108854 | I19: 108854 | J19: 95977 | K19: 86158 | L19: 86158 | M19: 86158 | N19: 157126 | O19: 157126 | P19: 163034 | Q19: 158301 | R19: 158301 | S19: 158301 | T19: 165280 | U19: =AVERAGE(C19:T19) -> 122583.44
B20: COIL SLITTING | C20: 1273844 | D20: 1256321 | E20: 1083313 | F20: 1151949 | G20: 1091481 | H20: 1091481 | I20: 1051193 | J20: 855860 | K20: 833142 | L20: 832186 | M20: 784653 | N20: 719143 | O20: 661402 | P20: 644111 | Q20: 963067 | R20: 976634 | S20: 1031777 | T20: 986054 | U20: =AVERAGE(C20:T20) -> 960422.83
B21: PRD | C21: 160610 | D21: 162940 | E21: 252073 | F21: 108925 | G21: 116288 | H21: 117029 | I21: 160517 | J21: 125180 | K21: 111025 | L21: 73669 | M21: 114080 | N21: 92810 | O21: 857862 | P21: 118275 | Q21: 235373 | R21: 219774 | S21: 122762 | T21: 113137 | U21: =AVERAGE(C21:T21) -> 181240.5
B22: QA | C22: 80492 | D22: 108560 | E22: 119877 | F22: 108572 | G22: 133797 | H22: 131253 | I22: 109733 | J22: 63412 | K22: 61307 | L22: 51680 | M22: 55860 | N22: 66564 | O22: 223901 | P22: 196468 | Q22: 137721 | R22: 141878 | S22: 137518 | T22: 148401 | U22: =AVERAGE(C22:T22) -> 115388.56
B23: DOWNGRADE | C23: 220371 | D23: 220371 | E23: 225086 | F23: 225086 | G23: 225086 | H23: 225086 | I23: 225086 | J23: 231302 | K23: 231302 | L23: 231302 | M23: 232281 | N23: 235312 | O23: 235312 | P23: 235312 | Q23: 235312 | R23: 235312 | S23: 235312 | T23: 239029 | U23: =AVERAGE(C23:T23) -> 230181.11
A24: LIMBAH | B24: DROSS | C24: 4538 | D24: 5151 | E24: 5151 | F24: 5151 | G24: 5151 | H24: 0 | I24: 0 | J24: 550 | K24: 3247 | L24: 3247 | M24: 0 | N24: 0 | O24: 0 | P24: 540 | Q24: 1144 | R24: 1144 | S24: 1144 | T24: 1144 | U24: =AVERAGE(C24:T24) -> 2072.3333
B25: PUP COIL | C25: 19627 | D25: 19535 | E25: 19535 | F25: 19535 | G25: 19535 | H25: 19535 | I25: 19535 | J25: 19535 | K25: 19613 | L25: 19613 | M25: 19627 | N25: 19627 | O25: 19627 | P25: 19613 | Q25: 19613 | R25: 19613 | S25: 19613 | T25: 19613 | U25: =AVERAGE(C25:T25) -> 19585.778

Sheet KAPASITAS MAR
A1: CRC - MARET 2026
A2: TGL | B2: STOCK | D2: TOTAL STOCK | E2: KAP | F2: TREND
B3: WH | C3: PRD & QA
A4: 2 | B4: =MAR!C5/1000 -> 1994.535 | C4: =(MAR!C10+MAR!C11)/1000 -> 641.131 | D4: =B4+C4 -> 2635.666 | E4: 6760 | F4: =D4/E4 -> 0.38989142
A5: 3 | B5: =MAR!D5/1000 -> 2459.63 | C5: =(MAR!D10+MAR!D11)/1000 -> 645.46 | D5: =B5+C5 -> 3105.09 | E5: 6760 | F5: =D5/E5 -> 0.45933284
A6: 4 | B6: =MAR!E5/1000 -> 2712.15 | C6: =(MAR!E10+MAR!E11)/1000 -> 290.239 | D6: =B6+C6 -> 3002.389 | E6: 6760 | F6: =D6/E6 -> 0.44414038
A7: 5 | B7: =MAR!F5/1000 -> 2694.98 | C7: =(MAR!F10+MAR!F11)/1000 -> 400.465 | D7: =B7+C7 -> 3095.445 | E7: 6760 | F7: =D7/E7 -> 0.45790607
A8: 6 | B8: =MAR!G5/1000 -> 2093.44 | C8: =(MAR!G10+MAR!G11)/1000 -> 466.829 | D8: =B8+C8 -> 2560.269 | E8: 6760 | F8: =D8/E8 -> 0.37873802
A9: 7 | B9: =MAR!H5/1000 -> 1586.58 | C9: =(MAR!H10+MAR!H11)/1000 -> 602.441 | D9: =B9+C9 -> 2189.021 | E9: 6760 | F9: =D9/E9 -> 0.32381967
A10: 9 | B10: =MAR!I5/1000 -> 1486.86 | C10: =(MAR!I10+MAR!I11)/1000 -> 85.432 | D10: =B10+C10 -> 1572.292 | E10: 6760 | F10: =D10/E10 -> 0.23258757
A11: 10 | B11: =MAR!J5/1000 -> 1604.79 | C11: =(MAR!J10+MAR!J11)/1000 -> 72.674 | D11: =B11+C11 -> 1677.464 | E11: 6760 | F11: =D11/E11 -> 0.24814556
A12: 11 | B12: =MAR!K5/1000 -> 1680.495 | C12: =(MAR!K10+MAR!K11)/1000 -> 72.674 | D12: =B12+C12 -> 1753.169 | E12: 6760 | F12: =D12/E12 -> 0.25934453
A13: 12 | B13: =MAR!L5/1000 -> 2255.16 | C13: =(MAR!L10+MAR!L11)/1000 -> 72.674 | D13: =B13+C13 -> 2327.834 | E13: 6760 | F13: =D13/E13 -> 0.34435414
A14: 13 | B14: =MAR!M5/1000 -> 2255.16 | C14: =(MAR!M10+MAR!M11)/1000 -> 72.674 | D14: =B14+C14 -> 2327.834 | E14: 6760 | F14: =D14/E14 -> 0.34435414
A15: 14 | B15: =MAR!N5/1000 -> 3045.02 | C15: =(MAR!N10+MAR!N11)/1000 -> 421.572 | D15: =B15+C15 -> 3466.592 | E15: 6760 | F15: =D15/E15 -> 0.51280947
A16: 16 | B16: =MAR!O5/1000 -> 1765.585 | C16: =(MAR!O10+MAR!O11)/1000 -> 376.648 | D16: =B16+C16 -> 2142.233 | E16: 6760 | F16: =D16/E16 -> 0.31689837
A17: 17 | B17: =MAR!P5/1000 -> 1328.52 | C17: =(MAR!P10+MAR!P11)/1000 -> 211.125 | D17: =B17+C17 -> 1539.645 | E17: 6760 | F17: =D17/E17 -> 0.22775814
A18: 18 | B18: =466460/1000 -> 466.46 | C18: =(MAR!Q10+MAR!Q11)/1000 -> 80.318 | D18: =B18+C18 -> 546.778 | E18: 6760 | F18: =D18/E18 -> 0.08088432
A19: 28 | B19: =MAR!R5/1000 -> 629.095 | C19: =(MAR!R10+MAR!R11)/1000 -> 76.278 | D19: =B19+C19 -> 705.373 | E19: 6760 | F19: =D19/E19 -> 0.10434512 | H19: PERHITUNGAN KAPASITAS : RATA-RATA BERAT PER COIL 20 TON
A20: 30 | B20: =MAR!S5/1000 -> 843.255 | C20: =(MAR!S10+MAR!S11)/1000 -> 79.115 | D20: =B20+C20 -> 922.37 | E20: 6760 | F20: =D20/E20 -> 0.13644527 | H20: Kapasitas | J20: 6760 | K20: Ton
A21: 31 | B21: =MAR!T5/1000 -> 1632.645 | C21: =(MAR!T10+MAR!T11)/1000 -> 151.893 | D21: =B21+C21 -> 1784.538 | E21: 6760 | F21: =D21/E21 -> 0.26398491 | H21: Posisi Stock 31 Mar 26 | J21: 1785 | K21: Ton
A22: AVERAGE | B22: =AVERAGE(B4:B21) -> 1807.4644 | C22: =AVERAGE(C4:C21) -> 267.75789 | D22: =AVERAGE(D4:D21) -> 2075.2223 | E22: =AVERAGE(E4:E21) -> 6760 | F22: =AVERAGE(F4:F21) -> 0.30698555 | H22: Kapasitas (%) | J22: =J21/J20 -> 0.26405325 | K22: Ton
A23: Stock tertinggi | B23: =MAX(B4:B21) -> 3045.02 | C23: =MAX(C4:C21) -> 645.46 | D23: =MAX(D4:D21) -> 3466.592 | E23: 6760 | F23: =D23/E23 -> 0.51280947 | H23: Kapasitas tersisa | J23: =100%-J22 -> 0.73594675 | K23: Ton
A26: BARANG JADI MARET 2026
A27: TGL | B27: STOCK | D27: TOTAL STOCK | E27: KAP | F27: TREND
B28: WH | C28: PRD & QA
A29: 2 | B29: =(MAR!C12+MAR!C13+MAR!C14+MAR!C15+MAR!C16+MAR!C17+MAR!C18+MAR!C19+MAR!C20+MAR!C23)/1000 -> 6752.0595 | C29: =(MAR!C21+MAR!C22)/1000 -> 241.102 | D29: =B29+C29 -> 6993.1615 | E29: 12000 | F29: =D29/E29 -> 0.58276346
A30: 3 | B30: =(MAR!D12+MAR!D13+MAR!D14+MAR!D15+MAR!D16+MAR!D17+MAR!D18+MAR!D19+MAR!D20+MAR!D23)/1000 -> 6952.8305 | C30: =(MAR!D21+MAR!D22)/1000 -> 271.5 | D30: =B30+C30 -> 7224.3305 | E30: 12000 | F30: =D30/E30 -> 0.60202754
A31: 4 | B31: =(MAR!E12+MAR!E13+MAR!E14+MAR!E15+MAR!E16+MAR!E17+MAR!E18+MAR!E19+MAR!E20+MAR!E23)/1000 -> 6205.7035 | C31: =(MAR!E21+MAR!E22)/1000 -> 371.95 | D31: =B31+C31 -> 6577.6535 | E31: 12000 | F31: =D31/E31 -> 0.54813779
A32: 5 | B32: =(MAR!F12+MAR!F13+MAR!F14+MAR!F15+MAR!F16+MAR!F17+MAR!F18+MAR!F19+MAR!F20+MAR!F23)/1000 -> 5982.4615 | C32: =(MAR!F21+MAR!F22)/1000 -> 217.497 | D32: =B32+C32 -> 6199.9585 | E32: 12000 | F32: =D32/E32 -> 0.51666321
A33: 6 | B33: =(MAR!G12+MAR!G13+MAR!G14+MAR!G15+MAR!G16+MAR!G17+MAR!G18+MAR!G19+MAR!G20+MAR!G23)/1000 -> 6007.512 | C33: =(MAR!G21+MAR!G22)/1000 -> 250.085 | D33: =B33+C33 -> 6257.597 | E33: 12000 | F33: =D33/E33 -> 0.52146642
A34: 7 | B34: =(MAR!H12+MAR!H13+MAR!H14+MAR!H15+MAR!H16+MAR!H17+MAR!H18+MAR!H19+MAR!H20+MAR!H23)/1000 -> 6272.337 | C34: =(MAR!H21+MAR!H22)/1000 -> 248.282 | D34: =B34+C34 -> 6520.619 | E34: 12000 | F34: =D34/E34 -> 0.54338492
A35: 9 | B35: =(MAR!I12+MAR!I13+MAR!I14+MAR!I15+MAR!I16+MAR!I17+MAR!I18+MAR!I19+MAR!I20+MAR!I23)/1000 -> 6741.508 | C35: =(MAR!I21+MAR!I22)/1000 -> 270.25 | D35: =B35+C35 -> 7011.758 | E35: 12000 | F35: =D35/E35 -> 0.58431317
A36: 10 | B36: =(MAR!J12+MAR!J13+MAR!J14+MAR!J15+MAR!J16+MAR!J17+MAR!J18+MAR!J19+MAR!J20+MAR!J23)/1000 -> 6407.954 | C36: =(MAR!J21+MAR!J22)/1000 -> 188.592 | D36: =B36+C36 -> 6596.546 | E36: 12000 | F36: =D36/E36 -> 0.54971217
A37: 11 | B37: =(MAR!K12+MAR!K13+MAR!K14+MAR!K15+MAR!K16+MAR!K17+MAR!K18+MAR!K19+MAR!K20+MAR!K23)/1000 -> 6283.798 | C37: =(MAR!K21+MAR!K22)/1000 -> 172.332 | D37: =B37+C37 -> 6456.13 | E37: 12000 | F37: =D37/E37 -> 0.53801083
A38: 12 | B38: =(MAR!L12+MAR!L13+MAR!L14+MAR!L15+MAR!L16+MAR!L17+MAR!L18+MAR!L19+MAR!L20+MAR!L23)/1000 -> 6011.785 | C38: =(MAR!L21+MAR!L22)/1000 -> 125.349 | D38: =B38+C38 -> 6137.134 | E38: 12000 | F38: =D38/E38 -> 0.51142783
A39: 13 | B39: =(MAR!M12+MAR!M13+MAR!M14+MAR!M15+MAR!M16+MAR!M17+MAR!M18+MAR!M19+MAR!M20+MAR!M23)/1000 -> 5794.071 | C39: =(MAR!M21+MAR!M22)/1000 -> 169.94 | D39: =B39+C39 -> 5964.011 | E39: 12000 | F39: =D39/E39 -> 0.49700092
A40: 14 | B40: =(MAR!N12+MAR!N13+MAR!N14+MAR!N15+MAR!N16+MAR!N17+MAR!N18+MAR!N19+MAR!N20+MAR!N23)/1000 -> 5919.513 | C40: =(MAR!N21+MAR!N22)/1000 -> 159.374 | D40: =B40+C40 -> 6078.887 | E40: 12000 | F40: =D40/E40 -> 0.50657392
A41: 16 | B41: =(MAR!O12+MAR!O13+MAR!O14+MAR!O15+MAR!O16+MAR!O17+MAR!O18+MAR!O19+MAR!O20+MAR!O23)/1000 -> 6394.127 | C41: =(MAR!O21+MAR!O22)/1000 -> 1081.763 | D41: =B41+C41 -> 7475.89 | E41: 12000 | F41: =D41/E41 -> 0.62299083
A42: 17 | B42: =(MAR!P12+MAR!P13+MAR!P14+MAR!P15+MAR!P16+MAR!P17+MAR!P18+MAR!P19+MAR!P20+MAR!P23)/1000 -> 6811.583 | C42: =(MAR!P21+MAR!P22)/1000 -> 314.743 | D42: =B42+C42 -> 7126.326 | E42: 12000 | F42: =D42/E42 -> 0.5938605
...

Sheet APR
A1: POSISI STOCK TML APRIL 2026 ( KG )
A3: STOCK | C3: 1 | D3: 2 | E3: 4 | F3: 6 | G3: 7 | H3: 8 | I3: 9 | J3: 10 | K3: 11 | L3: 13 | M3: 14 | N3: 15 | O3: 16 | P3: 17 | Q3: 18 | R3: 20 | S3: 21 | T3: 22 | U3: 23 | V3: 24 | W3: 25 | X3: 27 | Y3: 28 | Z3: 29 | AA3: 30 | AB3: AVERAGE
A5: BAHAN BAKU | B5: CRC | C5: 2700385 | D5: 1388650 | E5: 2168631 | F5: 2125800 | G5: 1669340 | H5: 1922015 | I5: 2315645 | J5: 1952395 | K5: 1827725 | L5: 2718935 | M5: 2014530 | N5: 1730515 | O5: 1782540 | P5: 2006415 | Q5: 2099420 | R5: 1795620 | S5: 1749745 | T5: 1633073 | U5: 3428473 | V5: 2921425 | W5: 3104900 | X5: 2876865 | Y5: 2674855 | Z5: 2142190 | AA5: 3288410 | AB5: =AVERAGE(C5:AA5) -> 2241539.9
B6: ALLUMUNIUM | C6: 321492 | D6: 307372 | E6: 284844 | F6: 266540 | G6: 255276 | H6: 255276 | I6: 232776 | J6: 220096 | K6: 245233 | L6: 225513 | M6: 505835 | N6: 500199 | O6: 500199 | P6: 488907 | Q6: 479057 | R6: 457989 | S6: 445299 | T6: 431191 | U6: 422733 | V6: 414277 | W6: 404397 | X6: 380391 | Y6: 364901 | Z6: 357897 | AA6: 342417 | AB6: =AVERAGE(C6:AA6) -> 364404.28
B7: ZINC | C7: 494284 | D7: 483235 | E7: 472173 | F7: 454473 | G7: 446722 | H7: 446722 | I7: 431264 | J7: 426842 | K7: 413586 | L7: 403631 | M7: 396997 | N7: 390359 | O7: 390359 | P7: 385932 | Q7: 375971 | R7: 367130 | S7: 360513 | T7: 349437 | U7: 494953 | V7: 488326 | W7: 481699 | X7: 542516 | Y7: 533676 | Z7: 527039 | AA7: 515966 | AB7: =AVERAGE(C7:AA7) -> 442952.2
B8: ALKALI | C8: 6000 | D8: 3600 | E8: 3600 | F8: 3600 | G8: 3600 | H8: 3600 | I8: 4800 | J8: 4800 | K8: 4800 | L8: 4800 | M8: 2400 | N8: 390359 | O8: 2400 | P8: 2400 | Q8: 2400 | R8: 2400 | S8: 2400 | T8: 2400 | U8: 3600 | V8: 3600 | W8: 3600 | X8: 3600 | Y8: 7200 | Z8: 7200 | AA8: 3600 | AB8: =AVERAGE(C8:AA8) -> 19310.36
B9: RESIN | C9: 32238 | D9: 32088 | E9: 28088 | F9: 23088 | G9: 20488 | H9: 20488 | I9: 19488 | J9: 16270 | K9: 16120 | L9: 8120 | M9: 8120 | N9: 8120 | O9: 18120 | P9: 18120 | Q9: 12820 | R9: 12820 | S9: 9370 | T9: 8130 | U9: 15130 | V9: 15130 | W9: 12130 | X9: 9010 | Y9: 23010 | Z9: 21010 | AA9: 20010 | AB9: =AVERAGE(C9:AA9) -> 17101.04
B10: PRD | C10: 239141 | D10: 228767 | E10: 161813 | F10: 277723 | G10: 262261 | H10: 243208 | I10: 252258 | J10: 268241 | K10: 217713 | L10: 287083 | M10: 110343 | N10: 285199 | O10: 284522 | P10: 395094 | Q10: 313944 | R10: 303136 | S10: 441327 | T10: 506473 | U10: 354481 | V10: 351643 | W10: 380227 | X10: 382478 | Y10: 264063 | Z10: 319293 | AA10: 322992 | AB10: =AVERAGE(C10:AA10) -> 298136.92
B11: QA | C11: 25753 | D11: 17605 | E11: 15435 | F11: 15435 | G11: 15435 | H11: 31965 | I11: 295 | J11: 295 | K11: 770 | L11: 770 | M11: 770 | N11: 770 | O11: 770 | P11: 770 | Q11: 21090 | R11: 37940 | S11: 37940 | T11: 94420 | U11: 74100 | V11: 155450 | W11: 248610 | X11: 219890 | Y11: 219890 | Z11: 219890 | AA11: 219890 | AB11: =AVERAGE(C11:AA11) -> 67037.92
A12: BARANG JADI | B12: NEXALUME PRIME | C12: 2246144 | D12: 2623723 | E12: 2541392 | F12: 3606571 | G12: 3310859 | H12: 3102402 | I12: 3095317 | J12: 3658549 | K12: 3551964 | L12: 3975457 | M12: 3423923 | N12: 2949266 | O12: 2476209 | P12: 2005151 | Q12: 1804009 | R12: 2643449 | S12: 2664620 | T12: 2453160 | U12: 2451048 | V12: 2417047 | W12: 2672659 | X12: 2351438 | Y12: 2284109 | Z12: 2008945 | AA12: 1818462 | AB12: =AVERAGE(C12:AA12) -> 2725434.9
B13: TATALUME PRIME | C13: 259676 | D13: 259676 | E13: 275960 | F13: 275960 | G13: 259676 | H13: 264248 | I13: 279992 | J13: 240019 | K13: 283511 | L13: 278094 | M13: 345302 | N13: 331315 | O13: 318870 | P13: 209172 | Q13: 233650 | R13: 382141 | S13: 361936 | T13: 327603 | U13: 347279 | V13: 367925 | W13: 386935 | X13: 497582 | Y13: 497582 | Z13: 477486 | AA13: 445587 | AB13: =AVERAGE(C13:AA13) -> 328287.08
B14: NEXCOLOR PRIME | C14: 21353 | D14: 51691 | E14: 51691 | F14: 51709 | G14: 51709 | H14: 80818 | I14: 80818 | J14: 80818 | K14: 80818 | L14: 80818 | M14: 80818 | N14: 50629 | O14: 50629 | P14: 50629 | Q14: 50629 | R14: 50629 | S14: 50629 | T14: 50629 | U14: 50629 | V14: 47990 | W14: 47990 | X14: 47990 | Y14: 67362 | Z14: 67362 | AA14: 63001 | AB14: =AVERAGE(C14:AA14) -> 58391.52
B15: NEXIUM PRIME | C15: 418066 | D15: 389799 | E15: 389799 | F15: 389799 | G15: 358620 | H15: 358620 | I15: 371255 | J15: 375252 | K15: 374777 | L15: 374777 | M15: 386776 | N15: 380808 | O15: 380808 | P15: 380808 | Q15: 380808 | R15: 380808 | S15: 380715 | T15: 380715 | U15: 375393 | V15: 375393 | W15: 360880 | X15: 360880 | Y15: 360880 | Z15: 336947 | AA15: 334252 | AB15: =AVERAGE(C15:AA15) -> 374305.4
B16: COIL TATA SENTOSA | C16: 961087 | D16: 1079289 | E16: 1079289 | F16: 1079289 | G16: 1079289 | H16: 1274649 | I16: 1274649 | J16: 1387406 | K16: 1387406 | L16: 1387406 | M16: 1372881 | N16: 1372881 | O16: 1372881 | P16: 1372881 | Q16: 1372881 | R16: 1372881 | S16: 1372881 | T16: 1372881 | U16: 1358450 | V16: 1358450 | W16: 1515741 | X16: 1515741 | Y16: 1482803 | Z16: 1482803 | AA16: 1482803 | AB16: =AVERAGE(C16:AA16) -> 1326783.9
B17: COIL TATALOGAM | C17: 1736419 | D17: 1495946 | E17: 1495946 | F17: 1495946 | G17: 1495946 | H17: 1495946 | I17: 1495946 | J17: 844413 | K17: 844413 | L17: 812219 | M17: 866362 | N17: 866362 | O17: 829094 | P17: 829094 | Q17: 719878 | R17: 719878 | S17: 719878 | T17: 719878 | U17: 719878 | V17: 952060 | W17: 1221171 | X17: 1473455 | Y17: 1473455 | Z17: 1473455 | AA17: 1473455 | AB17: =AVERAGE(C17:AA17) -> 1130819.7
B18: NEXALUME MEDIUM | C18: 729785 | D18: 729785 | E18: 729785 | F18: 729785 | G18: 725785 | H18: 725785 | I18: 729195 | J18: 729195 | K18: 729195 | L18: 729195 | M18: 723781 | N18: 723781 | O18: 723781 | P18: 723781 | Q18: 723781 | R18: 723781 | S18: 723781 | T18: 723781 | U18: 767840 | V18: 767840 | W18: 763550 | X18: 763550 | Y18: 763550 | Z18: 763550 | AA18: 730319 | AB18: =AVERAGE(C18:AA18) -> 735917.48
B19: NEXALUME SECOND | C19: 165280 | D19: 165280 | E19: 165280 | F19: 165280 | G19: 176102 | H19: 176102 | I19: 176102 | J19: 176102 | K19: 176102 | L19: 176102 | M19: 159344 | N19: 159344 | O19: 159344 | P19: 159344 | Q19: 159344 | R19: 159344 | S19: 159344 | T19: 159344 | U19: 209072 | V19: 209072 | W19: 212073 | X19: 212073 | Y19: 212073 | Z19: 212073 | AA19: 204364 | AB19: =AVERAGE(C19:AA19) -> 178531.36
B20: COIL SLITTING | C20: 872707 | D20: 834350 | E20: 939203 | F20: 938723 | G20: 1026200 | H20: 1127482 | I20: 1244352 | J20: 1358141 | K20: 1547541 | L20: 1549139 | M20: 1665836 | N20: 1758332 | O20: 1889970 | P20: 1821315 | Q20: 1836375 | R20: 1905626 | S20: 1935575 | T20: 1942841 | U20: 1933516 | V20: 2035385 | W20: 2012355 | X20: 1866759 | Y20: 1823578 | Z20: 1716921 | AA20: 1555580 | AB20: =AVERAGE(C20:AA20) -> 1565512.1
B21: PRD | C21: 276649 | D21: 314578 | E21: 512238 | F21: 736888 | G21: 762318 | H21: 990659 | I21: 768186 | J21: 619963 | K21: 623581 | L21: 1080788 | M21: 1088320 | N21: 855849 | O21: 613124 | P21: 518214 | Q21: 550454 | R21: 507530 | S21: 362250 | T21: 454475 | U21: 567438 | V21: 552398 | W21: 395911 | X21: 1216499 | Y21: 1327902 | Z21: 1372866 | AA21: 1278609 | AB21: =AVERAGE(C21:AA21) -> 733907.48
B22: QA | C22: 126717 | D22: 150161 | E22: 146538 | F22: 128105 | G22: 132543 | H22: 196828 | I22: 125398 | J22: 123974 | K22: 121693 | L22: 121627 | M22: 110518 | N22: 87845 | O22: 87845 | P22: 87405 | Q22: 97670 | R22: 105727 | S22: 102223 | T22: 111180 | U22: 89845 | V22: 103675 | W22: 103675 | X22: 107484 | Y22: 112610 | Z22: 104167 | AA22: 128222 | AB22: =AVERAGE(C22:AA22) -> 116547
B23: DOWNGRADE | C23: 239029 | D23: 239029 | E23: 244283 | F23: 246771 | G23: 249345 | H23: 249747 | I23: 249747 | J23: 249747 | K23: 249747 | L23: 249747 | M23: 250370 | N23: 250370 | O23: 250370 | P23: 253262 | Q23: 253262 | R23: 256814 | S23: 256814 | T23: 256814 | U23: 256854 | V23: 256854 | W23: 256854 | X23: 260669 | Y23: 260669 | Z23: 260669 | AA23: 260669 | AB23: =AVERAGE(C23:AA23) -> 252340.24
A24: LIMBAH | B24: DROSS | C24: 1144 | D24: 1728 | E24: 1728 | F24: 2296.5 | G24: 2846 | H24: 2846 | I24: 2846 | J24: 3512 | K24: 3512 | L24: 4187 | M24: 5039 | N24: 5039 | O24: 5039 | P24: 1670.5 | Q24: 1670.5 | R24: 2821 | S24: 2821 | T24: 3405.5 | U24: 3405.5 | V24: 3405.5 | W24: 3676.5 | X24: 3676.5 | Y24: 4940 | Z24: 5565 | AA24: 5565 | AB24: =AVERAGE(C24:AA24) -> 3375.4
B25: PUP COIL | C25: 19613 | D25: 19613 | E25: 19613 | F25: 19613 | G25: 19613 | H25: 21783 | I25: 21783 | J25: 21783 | K25: 21783 | L25: 21783 | M25: 21783 | N25: 21783 | O25: 21783 | P25: 21783 | Q25: 21783 | R25: 21783 | S25: 21783 | T25: 21783 | U25: 21783 | V25: 21783 | W25: 21783 | X25: 21783 | Y25: 21783 | Z25: 21783 | AA25: 21783 | AB25: =AVERAGE(C25:AA25) -> 21349

Sheet KAPASITAS APR
A1: CRC - APRIL 2026
A2: TGL | B2: STOCK | D2: TOTAL STOCK | E2: KAP | F2: TREND
B3: WH | C3: PRD & QA
A4: 1 | B4: =APR!C5/1000 -> 2700.385 | C4: =(APR!C10+APR!C11)/1000 -> 264.894 | D4: =B4+C4 -> 2965.279 | E4: 6760 | F4: =D4/E4 -> 0.43865074
A5: 2 | B5: =APR!D5/1000 -> 1388.65 | C5: =(APR!D10+APR!D11)/1000 -> 246.372 | D5: =B5+C5 -> 1635.022 | E5: 6760 | F5: =D5/E5 -> 0.24186716
A6: 4 | B6: =APR!E5/1000 -> 2168.631 | C6: =(APR!E10+APR!E11)/1000 -> 177.248 | D6: =B6+C6 -> 2345.879 | E6: 6760 | F6: =D6/E6 -> 0.34702352
A7: 6 | B7: =APR!F5/1000 -> 2125.8 | C7: =(APR!F10+APR!F11)/1000 -> 293.158 | D7: =B7+C7 -> 2418.958 | E7: 6760 | F7: =D7/E7 -> 0.35783402
A8: 7 | B8: =APR!G5/1000 -> 1669.34 | C8: =(APR!G10+APR!G11)/1000 -> 277.696 | D8: =B8+C8 -> 1947.036 | E8: 6760 | F8: =D8/E8 -> 0.28802308
A9: 8 | B9: =APR!H5/1000 -> 1922.015 | C9: =(APR!H10+APR!H11)/1000 -> 275.173 | D9: =B9+C9 -> 2197.188 | E9: 6760 | F9: =D9/E9 -> 0.32502781
A10: 9 | B10: =APR!I5/1000 -> 2315.645 | C10: =(APR!I10+APR!I11)/1000 -> 252.553 | D10: =B10+C10 -> 2568.198 | E10: 6760 | F10: =D10/E10 -> 0.37991095
A11: 10 | B11: =APR!J5/1000 -> 1952.395 | C11: =(APR!J10+APR!J11)/1000 -> 268.536 | D11: =B11+C11 -> 2220.931 | E11: 6760 | F11: =D11/E11 -> 0.32854009
A12: 11 | B12: =APR!K5/1000 -> 1827.725 | C12: =(APR!K10+APR!K11)/1000 -> 218.483 | D12: =B12+C12 -> 2046.208 | E12: 6760 | F12: =D12/E12 -> 0.30269349
A13: 13 | B13: =APR!L5/1000 -> 2718.935 | C13: =(APR!L10+APR!L11)/1000 -> 287.853 | D13: =B13+C13 -> 3006.788 | E13: 6760 | F13: =D13/E13 -> 0.44479112
A14: 14 | B14: =APR!M5/1000 -> 2014.53 | C14: =(APR!M10+APR!M11)/1000 -> 111.113 | D14: =B14+C14 -> 2125.643 | E14: 6760 | F14: =D14/E14 -> 0.31444423
A15: 15 | B15: =APR!N5/1000 -> 1730.515 | C15: =(APR!N10+APR!N11)/1000 -> 285.969 | D15: =B15+C15 -> 2016.484 | E15: 6760 | F15: =D15/E15 -> 0.29829645
A16: 16 | B16: =APR!O5/1000 -> 1782.54 | C16: =(APR!O10+APR!O11)/1000 -> 285.292 | D16: =B16+C16 -> 2067.832 | E16: 6760 | F16: =D16/E16 -> 0.30589231
A17: 17 | B17: =APR!P5/1000 -> 2006.415 | C17: =(APR!P10+APR!P11)/1000 -> 395.864 | D17: =B17+C17 -> 2402.279 | E17: 6760 | F17: =D17/E17 -> 0.35536672
A18: 18 | B18: =APR!Q5/1000 -> 2099.42 | C18: =(APR!Q10+APR!Q11)/1000 -> 335.034 | D18: =B18+C18 -> 2434.454 | E18: 6760 | F18: =D18/E18 -> 0.36012633
A19: 20 | B19: =APR!R5/1000 -> 1795.62 | C19: =(APR!R10+APR!R11)/1000 -> 341.076 | D19: =B19+C19 -> 2136.696 | E19: 6760 | F19: =D19/E19 -> 0.31607929 | H19: PERHITUNGAN KAPASITAS : RATA-RATA BERAT PER COIL 20 TON
A20: 21 | B20: =APR!S5/1000 -> 1749.745 | C20: =(APR!S10+APR!S11)/1000 -> 479.267 | D20: =B20+C20 -> 2229.012 | E20: 6760 | F20: =D20/E20 -> 0.3297355 | H20: Kapasitas | J20: 6760 | K20: Ton
A21: 22 | B21: =APR!T5/1000 -> 1633.073 | C21: =(APR!T10+APR!T11)/1000 -> 600.893 | D21: =B21+C21 -> 2233.966 | E21: 6760 | F21: =D21/E21 -> 0.33046834 | H21: Posisi Stock 30 APR 26 | J21: 3831 | K21: Ton
A22: 23 | B22: =APR!U5/1000 -> 3428.473 | C22: =(APR!U10+APR!U11)/1000 -> 428.581 | D22: =B22+C22 -> 3857.054 | E22: 6760 | F22: =D22/E22 -> 0.57057012 | H22: Kapasitas (%) | J22: =J21/J20 -> 0.56671598 | K22: Ton
A23: 24 | B23: =APR!V5/1000 -> 2921.425 | C23: =(APR!V10+APR!V11)/1000 -> 507.093 | D23: =B23+C23 -> 3428.518 | E23: 6760 | F23: =D23/E23 -> 0.50717722 | H23: Kapasitas tersisa | J23: =100%-J22 -> 0.43328402 | K23: Ton
A24: 25 | B24: =APR!W5/1000 -> 3104.9 | C24: =(APR!W10+APR!W11)/1000 -> 628.837 | D24: =B24+C24 -> 3733.737 | E24: 6760 | F24: =D24/E24 -> 0.55232796
A25: 27 | B25: =APR!X5/1000 -> 2876.865 | C25: =(APR!X10+APR!X11)/1000 -> 602.368 | D25: =B25+C25 -> 3479.233 | E25: 6760 | F25: =D25/E25 -> 0.51467944
A26: 28 | B26: =APR!Y5/1000 -> 2674.855 | C26: =(APR!Y10+APR!Y11)/1000 -> 483.953 | D26: =B26+C26 -> 3158.808 | E26: 6760 | F26: =D26/E26 -> 0.46727929
A27: 29 | B27: =APR!Z5/1000 -> 2142.19 | C27: =(APR!Z10+APR!Z11)/1000 -> 539.183 | D27: =B27+C27 -> 2681.373 | E27: 6760 | F27: =D27/E27 -> 0.39665281
A28: 30 | B28: =APR!AA5/1000 -> 3288.41 | C28: =(APR!AA10+APR!AA11)/1000 -> 542.882 | D28: =B28+C28 -> 3831.292 | E28: 6760 | F28: =D28/E28 -> 0.56675917
A29: AVERAGE | B29: =AVERAGE(B4:B28) -> 2241.5399 | C29: =AVERAGE(C4:C28) -> 365.17484 | D29: =AVERAGE(D4:D28) -> 2606.7147 | E29: =AVERAGE(E4:E28) -> 6760 | F29: =AVERAGE(F4:F28) -> 0.38560869
A30: Stock tertinggi | B30: =MAX(B4:B28) -> 3428.473 | C30: =MAX(C4:C28) -> 628.837 | D30: =MAX(D4:D28) -> 3857.054 | E30: 6760 | F30: =D30/E30 -> 0.57057012
A33: BARANG JADI APRIL 2026
A34: TGL | B34: STOCK | D34: TOTAL STOCK | E34: KAP | F34: TREND
B35: WH | C35: PRD & QA
A36: 1 | B36: =(APR!C12+APR!C13+APR!C14+APR!C15+APR!C16+APR!C17+APR!C18+APR!C19+APR!C20+APR!C23)/1000 -> 7649.546 | C36: =(APR!C21+APR!C22)/1000 -> 403.366 | D36: =B36+C36 -> 8052.912 | E36: 12000 | F36: =D36/E36 -> 0.671076
A37: 2 | B37: =(APR!D12+APR!D13+APR!D14+APR!D15+APR!D16+APR!D17+APR!D18+APR!D19+APR!D20+APR!D23)/1000 -> 7868.568 | C37: =(APR!D21+APR!D22)/1000 -> 464.739 | D37: =B37+C37 -> 8333.307 | E37: 12000 | F37: =D37/E37 -> 0.69444225
A38: 4 | B38: =(APR!E12+APR!E13+APR!E14+APR!E15+APR!E16+APR!E17+APR!E18+APR!E19+APR!E20+APR!E23)/1000 -> 7912.628 | C38: =(APR!E21+APR!E22)/1000 -> 658.776 | D38: =B38+C38 -> 8571.404 | E38: 12000 | F38: =D38/E38 -> 0.71428367
A39: 6 | B39: =(APR!F12+APR!F13+APR!F14+APR!F15+APR!F16+APR!F17+APR!F18+APR!F19+APR!F20+APR!F23)/1000 -> 8979.833 | C39: =(APR!F21+APR!F22)/1000 -> 864.993 | D39: =B39+C39 -> 9844.826 | E39: 12000 | F39: =D39/E39 -> 0.82040217
A40: 7 | B40: =(APR!G12+APR!G13+APR!G14+APR!G15+APR!G16+APR!G17+APR!G18+APR!G19+APR!G20+APR!G23)/1000 -> 8733.531 | C40: =(APR!G21+APR!G22)/1000 -> 894.861 | D40: =B40+C40 -> 9628.392 | E40: 12000 | F40: =D40/E40 -> 0.802366
A41: 8 | B41: =(APR!H12+APR!H13+APR!H14+APR!H15+APR!H16+APR!H17+APR!H18+APR!H19+APR!H20+APR!H23)/1000 -> 8855.799 | C41: =(APR!H21+APR!H22)/1000 -> 1187.487 | D41: =B41+C41 -> 10043.286 | E41: 12000 | F41: =D41/E41 -> 0.8369405
A42: 9 | B42: =(APR!I12+APR!I13+APR!I14+APR!I15+APR!I16+APR!I17+APR!I18+APR!I19+APR!I20+APR!I23)/1000 -> 8997.373 | C42: =(APR!I21+APR!I22)/1000 -> 893.584 | D42: =B42+C42 -> 9890.957 | E42: 12000 | F42: =D42/E42 -> 0.82424642
...

Sheet MEI
A1: POSISI STOCK TML MEI 2026 ( KG )
A3: STOCK | C3: 2 | D3: 4 | E3: 5 | F3: 6 | G3: 7 | H3: 8 | I3: 9 | J3: 11 | K3: 12 | L3: 13 | M3: 15 | N3: 16 | O3: 18 | P3: 19 | Q3: 20 | R3: 21 | S3: 22 | T3: 23 | U3: 25 | V3: 26 | W3: 28 | X3: 29 | Y3: 30 | Z3: AVERAGE
A5: BAHAN BAKU | B5: CRC | C5: 5170225 | D5: 4775185 | E5: 6067265 | F5: 5474065 | G5: 4322080 | H5: 7281325 | I5: 8064635 | J5: 7158285 | K5: 7130945 | L5: 6529325 | M5: 6129645 | N5: 5553665 | O5: 5337685 | P5: 5385080 | Q5: 5366990 | R5: 4630385 | S5: 4123145 | T5: 4420920 | U5: 3424905 | V5: 3684470 | W5: 2576180 | X5: 2702840 | Y5: 3478050 | Z5: =AVERAGE(C5:Y5) -> 5164665
B6: ALLUMUNIUM | C6: 338213 | D6: 312875 | E6: 300221 | F6: 287521 | G6: 274881 | H6: 265023 | I6: 252321 | J6: 267736 | K6: 267736 | L6: 267736 | M6: 255050 | N6: 245182 | O6: 218404 | P6: 205744 | Q6: 197330 | R6: 184636 | S6: 171960 | T6: 159300 | U6: 135350 | V6: 122678 | W6: 101643 | X6: 327822 | Y6: 345886 | Z6: =AVERAGE(C6:Y6) -> 239358.61
B7: ZINC | C7: 514860 | D7: 497210 | E7: 488387 | F7: 479574 | G7: 470766 | H7: 461954 | I7: 454235 | J7: 437701 | K7: 437701 | L7: 393517 | M7: 381379 | N7: 375879 | O7: 358254 | P7: 347232 | Q7: 345026 | R7: 333985 | S7: 325142 | T7: 318518 | U7: 304195 | V7: 444034 | W7: 430805 | X7: 426380 | Y7: 418674 | Z7: =AVERAGE(C7:Y7) -> 410669.91
B8: ALKALI | C8: 3600 | D8: 2400 | E8: 1200 | F8: 4800 | G8: 4800 | H8: 4800 | I8: 4800 | J8: 1200 | K8: 1200 | L8: 4800 | M8: 4800 | N8: 4800 | O8: 2400 | P8: 2400 | Q8: 2400 | R8: 6000 | S8: 6000 | T8: 6000 | U8: 6000 | V8: 3600 | W8: 1200 | X8: 1200 | Y8: 1200 | Z8: =AVERAGE(C8:Y8) -> 3547.8261
B9: RESIN | C9: 22010 | D9: 19275 | E9: 17275 | F9: 24275 | G9: 21275 | H9: 20475 | I9: 16475 | J9: 13275 | K9: 12275 | L9: 18825 | M9: 18125 | N9: 14125 | O9: 9975 | P9: 7120 | Q9: 5120 | R9: 19120 | S9: 17320 | T9: 15470 | U9: 10320 | V9: 21970 | W9: 17970 | X9: 16820 | Y9: 22820 | Z9: =AVERAGE(C9:Y9) -> 16596.087
B10: PRD | C10: 119719 | D10: 380962 | E10: 356752 | F10: 148212 | G10: 307763 | H10: 276767 | I10: 341602 | J10: 204803 | K10: 367113 | L10: 204112 | M10: 195184 | N10: 298254 | O10: 390335 | P10: 208400 | Q10: 237070 | R10: 280090 | S10: 268245 | T10: 254055 | U10: 361750 | V10: 378045 | W10: 279135 | X10: 269730 | Y10: 66090 | Z10: =AVERAGE(C10:Y10) -> 269312.52
B11: QA | C11: 219890 | D11: 258550 | E11: 270910 | F11: 270910 | G11: 271100 | H11: 271475 | I11: 271475 | J11: 271475 | K11: 271475 | L11: 271705 | M11: 303595 | N11: 327565 | O11: 328670 | P11: 328670 | Q11: 328845 | R11: 328845 | S11: 328845 | T11: 328845 | U11: 355910 | V11: 360440 | W11: 360440 | X11: 360440 | Y11: 360440 | Z11: =AVERAGE(C11:Y11) -> 306544.13
